File: data/Brass_kink.csv
Strain,Stress(Mpa)
0,0
2.96569E-06,0.542920315
5.80882E-06,0.636636853
8.75E-06,0.753861888
1.20833E-05,0.890783217
1.55147E-05,1.034693706
1.80392E-05,1.144611888
2.02451E-05,1.241823007
2.29412E-05,1.372708392
2.56618E-05,1.487391818
2.81618E-05,1.598263462
3.03186E-05,1.701510385
3.24755E-05,1.799039091
3.51961E-05,1.935007343
3.79902E-05,2.06621049
4.04412E-05,2.184070734
4.25735E-05,2.289859231
4.48039E-05,2.391517762
4.77941E-05,2.537016608
5.06618E-05,2.666631469
5.31618E-05,2.785127133
5.53431E-05,2.895681119
5.75735E-05,2.999563636
6.02451E-05,3.131084266
6.30637E-05,3.258157343
6.55392E-05,3.376335315
6.76961E-05,3.485300699
6.98284E-05,3.597442308
7.25E-05,3.734046503
7.52941E-05,3.872556294
7.79902E-05,4.012018881
8.01961E-05,4.123843357
8.23775E-05,4.234079545
8.5098E-05,4.370047552
8.78186E-05,4.504745455
9.03431E-05,4.628641608
9.25245E-05,4.739195455
9.47304E-05,4.858009091
9.7451E-05,5.011767483
0.000100123,5.155995455
0.00010277,5.294823077
0.000105098,5.408871329
0.000107255,5.522601923
0.000109877,5.668100699
0.000112426,5.800891958
0.000115025,5.937495455
0.000117328,6.04391958
0.000119485,6.159238811
0.000122108,6.30854965
0.000125,6.470567483
0.000127696,6.621784965
0.000130049,6.745681818
0.000131936,6.840986713
0.000134534,6.990614685
0.000137696,7.184718881
0.000140368,7.336253846
0.000142672,7.466504196
0.000144853,7.611685315
0.000147525,7.834064336
0.000150147,8.078997203
0.000152672,8.322342657
0.000155049,8.584431469
0.00015723,8.816339161
0.000159828,9.126715734
0.0001625,9.461870979
0.000165147,9.772247203
0.000167377,10.03465385
0.000169461,10.29007133
0.000171593,10.54072378
0.000174559,10.94386294
0.000177917,11.39846748
0.000180417,11.73012727
0.000182206,11.94964685
0.000183922,12.17170629
0.000186789,12.59708531
0.000190196,13.11967343
0.000193162,13.55299301
0.000195074,13.84176783
0.000197181,14.16008566
0.000199608,14.55432867
0.000202524,15.01846503
0.000205319,15.46703427
0.000207304,15.75993706
0.000208848,16.01217832
0.000210784,16.34638182
0.000213186,16.75492133
0.000216373,17.29053427
0.000219387,17.8325
0.000221691,18.19624825
0.00022402,18.56698392
0.00022674,19.04922832
0.000229534,19.55656573
0.000231569,19.87679231
0.000237034,20.90672028
0.000239877,21.4058007
0.00024076,21.5036458
0.000241716,21.66407692
0.000246127,22.48465385
0.000249216,23.18323776
0.000250417,23.30268531
0.000251422,23.35129021
0.000256324,24.47334755
0.000257721,24.66078322
0.000259387,24.66491259
0.00026348,25.85082168
0.000264608,25.99441434
0.000267402,26.28668182
0.000270025,27.12918007
0.000272206,27.18953846
0.000275735,28.2668028
0.000276299,28.23312413
0.000280588,29.13852098
0.000282132,29.4498549
0.000284363,29.57946678
0.000288284,30.76283916
0.000289118,30.78158182
0.000292623,31.43822727
0.000294461,31.97860979
0.000298162,32.68767657
0.000299632,33.11973077
0.000301667,33.1642028
0.000305172,34.43556818
0.000306422,34.23225175
0.000310515,35.66881818
0.000310907,35.36384266
0.000315294,36.73019406
0.000315637,36.54657343
0.000320441,37.86622727
0.000323946,38.68807552
0.000326569,39.26911538
0.00032902,39.85937413
0.000331348,40.39657168
0.000333725,40.98365035
0.000336324,41.61647552
0.000338946,42.2655035
0.000341348,42.84718392
0.00034375,43.42822378
0.000346127,44.0207028
0.00034875,44.67226923
0.00035125,45.29048252
0.000353578,45.86294056
0.000355882,46.48592308
0.000358235,47.07141608
0.000360809,47.71440559
0.000363309,48.38122028
0.000365809,49.01754196
0.00036826,49.61827972
0.000370637,50.22537063
0.000373211,50.86327273
0.00037576,51.48370979
0.000378211,52.10224476
0.000380515,52.6584965
0.000382794,53.26082867
0.00038527,53.89493007
0.000387868,54.61352098
0.00039049,55.32545455
0.000392917,55.88584266
0.000395221,56.45703846
0.000397696,57.12735315
0.00040027,57.77987063
0.000402794,58.45145455
0.000405196,59.06394406
0.000407549,59.61861888
0.000409853,60.24890559
0.000412353,60.86775175
0.000414926,61.57745105
0.000417328,62.2106014
0.000419632,62.82086713
0.000422108,63.45146853
0.000424657,64.12272727
0.000427206,64.7993986
0.000429559,65.43857692
0.000431789,65.98022727
0.000434167,66.61940559
0.000436716,67.29924126
0.000439338,68.02006294
0.00044174,68.63891608
0.000444118,69.23361189
0.000446495,69.88772378
0.000449142,70.62252448
0.000451642,71.23660839
0.000454167,71.95806294
0.000456471,72.54355245
0.000458701,73.09663636
0.000461176,73.81937063
0.000463774,74.51890559
0.000466275,75.18508392
0.000468701,75.83825175
0.000470858,76.3926049
0.000473382,77.08514685
0.000476005,77.78976923
0.000478652,78.51217832
0.000481005,79.13802448
0.000483235,79.66982517
0.000485735,80.36427972
0.00048826,81.07397902
0.00049076,81.76748252
0.000493186,82.44065385
0.000495417,83.00548951
0.000498015,83.7564965
0.000501141,84.46244532
0.000502661,84.77894315
0.000503802,85.08109951
0.000504943,85.38325587
0.000506084,85.68541222
0.000507224,85.98756858
0.000508365,86.28972494
0.000509506,86.59188129
0.000510646,86.89403765
0.000511787,87.19619401
0.000512928,87.49835036
0.000514829,87.77160481
0.00051711,88.0304083
0.000519392,88.28921179
0.000521673,88.54801528
0.000523955,88.80681877
0.000526236,89.06562225
0.000528517,89.32442574
0.000530799,89.58322923
0.00053308,89.84203272
0.000535362,90.10083621
0.000537643,90.44601701
0.000539924,90.83438645
0.000542205,91.2227559
0.000544487,91.61112535
0.000546768,91.9994948
0.000549049,92.38786425
0.000551331,92.77623369
0.000553612,93.16460314
0.000555893,93.55297259
0.000558175,93.94134204
0.000560456,94.27212661
0.000562737,94.57411876
0.000565019,94.8761109
0.0005673,95.17810304
0.000569582,95.48009518
0.000571863,95.78208732
0.000574144,96.08407947
0.000576426,96.38607161
0.000578707,96.68806375
0.000580989,96.99005589
0.000582509,97.29215751
0.00058365,97.59431387
0.000584791,97.89647022
0.000585932,98.19862658
0.000587072,98.50078293
0.000588213,98.80293929
0.000589354,99.10509565
0.000590494,99.407252
0.000591635,99.70940836
0.000592776,100.0115647
0.000593916,100.2849286
0.000595057,100.5438964
0.000596198,100.8028641
0.000597339,101.0618318
0.000598479,101.3207995
0.00059962,101.5797672
0.000600761,101.8387349
0.000601901,102.0977026
0.000603042,102.3566703
0.000604183,102.615638
0.000605323,102.8458133
0.000606464,103.0615924
0.000607605,103.2773714
0.000608746,103.4931505
0.000609886,103.7089295
0.000611027,103.9247086
0.000612168,104.1404876
0.000613308,104.3562667
0.000614449,104.5720457
0.00061559,104.7878248
0.000617491,105.0898716
0.000619772,105.4350524
0.000622053,105.7802332
0.000624335,106.125414
0.000626616,106.4705948
0.000628897,106.8157756
0.000631179,107.1609564
0.00063346,107.5061372
0.000635741,107.8513179
0.000638023,108.1964987
0.000640304,108.4840947
0.000642585,108.7428982
0.000644867,109.0017016
0.000647148,109.2605051
0.00064943,109.5193086
0.000651711,109.7781121
0.000653992,110.0369156
0.000656274,110.2957191
0.000658555,110.5545226
0.000660837,110.8133261
0.000663118,111.0721296
0.000665399,111.3309331
0.000667681,111.5897365
0.000669962,111.84854
0.000672244,112.1073435
0.000674525,112.366147
0.000676806,112.6249505
0.000679088,112.883754
0.000681369,113.1425575
0.000683651,113.401361
0.000685932,113.631372
0.000688213,113.8469869
0.000690494,114.0626017
0.000692776,114.2782165
0.000695057,114.4938313
0.000697338,114.7094462
0.00069962,114.925061
0.000701901,115.1406758
0.000704182,115.3562907
0.000706464,115.5719055
0.000708745,115.7875203
0.000711026,116.0031352
0.000713308,116.21875
0.000715589,116.4343648
0.000717871,116.6499797
0.000720152,116.8655945
0.000722433,117.0812094
0.000724715,117.2968242
0.000726996,117.512439
0.000729278,117.7280539
0.000731559,117.9436687
0.00073384,118.1592836
0.000736122,118.3748984
0.000738403,118.5905132
0.000740685,118.806128
0.000742966,119.0217429
0.000745247,119.2373577
0.000747529,119.4529725
0.00074981,119.6685874
0.000752092,119.8842022
0.000755133,120.0997075
0.000758555,120.3151582
0.000761977,120.5306088
0.000765399,120.7460594
0.000768821,120.96151
0.000772243,121.1769606
0.000775665,121.3924113
0.000779087,121.6078619
0.000782509,121.8233125
0.000785931,122.0387631
0.000789353,122.2542137
0.000792776,122.4696644
0.000796198,122.685115
0.00079962,122.9005656
0.000803042,123.1160162
0.000806464,123.3314668
0.000809886,123.5469175
0.000813308,123.7623681
0.00081673,123.9778187
0.000820152,124.1932693
0.000823574,124.4087199
0.000826996,124.6241706
0.000830418,124.8396212
0.00083384,125.0550718
0.000837262,125.2705224
0.000840684,125.485973
0.000844106,125.7014237
0.000847528,125.9168743
0.00085095,126.1323249
0.000854372,126.3477755
0.000857794,126.5056413
0.000861217,126.6347146
0.000864639,126.7637879
0.000868061,126.8928612
0.000871483,127.0219346
0.000874905,127.1510079
0.000878327,127.2800812
0.000881749,127.4091545
0.000885171,127.5382278
0.000888593,127.6673012
0.000891255,127.8252764
0.000893536,127.9977026
0.000895818,128.1701287
0.000898099,128.3425549
0.000900381,128.5149811
0.000902662,128.6874073
0.000904943,128.8598335
0.000907225,129.0322596
0.000909506,129.2046858
0.000911788,129.377112
0.000914829,129.5494287
0.000918251,129.7216907
0.000921673,129.8939527
0.000925095,130.0662146
0.000928517,130.2384766
0.000931939,130.4107386
0.000935361,130.5830005
0.000938783,130.7552625
0.000942205,130.9275245
0.000945627,131.0997864
0.00094981,131.3007314
0.000954372,131.5160178
0.000958935,131.7313042
0.000963498,131.9465906
0.000968061,132.161877
0.000972623,132.3771634
0.000977186,132.5924498
0.000981749,132.8077362
0.000986311,133.0230226
0.000990874,133.238309
0.000995437,133.4535954
0.001,133.6688818
0.001004562,133.8841682
0.001009125,134.0994546
0.001013688,134.314741
0.001018251,134.5300274
0.001022814,134.7453138
0.001027376,134.9606002
0.001031939,135.1758867
0.001036502,135.3911731
0.001040304,135.5777765
0.001043726,135.7500385
0.001047148,135.9223004
0.00105057,136.0945624
0.001053992,136.2668243
0.001057414,136.4390863
0.001060836,136.6113483
0.001064258,136.7836102
0.00106768,136.9558722
0.001071102,137.1281341
0.001075285,137.2714942
0.001079848,137.4004033
0.00108441,137.5293124
0.001088973,137.6582215
0.001093536,137.7871306
0.001098099,137.9160397
0.001102662,138.0449488
0.001107224,138.1738579
0.001111787,138.302767
0.00111635,138.4316761
0.001120913,138.6181701
0.001125476,138.8334565
0.001130038,139.0487429
0.001134601,139.2640293
0.001139164,139.4793157
0.001143726,139.6946021
0.001148289,139.9098885
0.001152852,140.1251749
0.001157414,140.3404614
0.001161977,140.5557478
0.00116654,140.7134493
0.001171103,140.8423584
0.001175665,140.9712675
0.001180228,141.1001766
0.001184791,141.2290857
0.001189353,141.3579947
0.001193916,141.4869038
0.001198479,141.6158129
0.001203041,141.744722
0.001207604,141.8736311
0.001211406,142.0026497
0.001214829,142.131723
0.001218251,142.2607963
0.001221673,142.3898696
0.001225095,142.518943
0.001228517,142.6480163
0.001231939,142.7770896
0.001235361,142.9061629
0.001238783,143.0352362
0.001242205,143.1643096
0.001245627,143.2933829
0.00124905,143.4224562
0.001252472,143.5515295
0.001255894,143.6806028
0.001259316,143.8096761
0.001262738,143.9387494
0.00126616,144.0678227
0.001269582,144.196896
0.001273004,144.3259694
0.001276426,144.4550427
0.001280609,144.5840065
0.001285172,144.7129156
0.001289734,144.8418247
0.001294297,144.9707338
0.00129886,145.0996429
0.001303422,145.228552
0.001307985,145.3574611
0.001312548,145.4863702
0.00131711,145.6152793
0.001321673,145.7441884
0.001326996,145.872988
0.0013327,146.0017329
0.001338403,146.1304778
0.001344106,146.2592227
0.00134981,146.3879675
0.001355513,146.5167124
0.001361217,146.6454573
0.00136692,146.7742022
0.001372623,146.9029471
0.001378327,147.0316919
0.00138403,147.1892293
0.001389734,147.3611628
0.001395437,147.5330963
0.00140114,147.7050299
0.001406844,147.8769634
0.001412547,148.048897
0.001418251,148.2208305
0.001423954,148.392764
0.001429657,148.5646976
0.001435361,148.7366311
0.001440304,148.8510893
0.001444867,148.9368097
0.001449429,149.0225301
0.001453992,149.1082506
0.001458555,149.193971
0.001463118,149.2796915
0.001467681,149.3654119
0.001472243,149.4511323
0.001476806,149.5368528
0.001481369,149.6225732
0.001485932,149.7082937
0.001490495,149.7940141
0.001495057,149.8797346
0.00149962,149.965455
0.001504183,150.0511755
0.001508745,150.1368959
0.001513308,150.2226164
0.001517871,150.3083368
0.001522433,150.3940573
0.001526996,150.4797777
0.001530798,150.5944001
0.001534221,150.7234734
0.001537643,150.8525467
0.001541065,150.98162
0.001544487,151.1106933
0.001547909,151.2397666
0.001551331,151.3688399
0.001554753,151.4979132
0.001558175,151.6269866
0.001561597,151.7560599
0.00156578,151.8562313
0.001570343,151.9419517
0.001574905,152.0276722
0.001579468,152.1133926
0.001584031,152.1991131
0.001588593,152.2848335
0.001593156,152.370554
0.001597719,152.4562744
0.001602281,152.5419949
0.001606844,152.6277153
0.001611407,152.7134358
0.00161597,152.7991562
0.001620532,152.8848766
0.001625095,152.9705971
0.001629658,153.0563175
0.00163422,153.142038
0.001638783,153.2277584
0.001643346,153.3134788
0.001647908,153.3991993
0.001652471,153.4849197
0.001657794,153.5705307
0.001663498,153.6560869
0.001669201,153.7416431
0.001674905,153.8271994
0.001680608,153.9127556
0.001686312,153.9983118
0.001692015,154.0838681
0.001697719,154.1694243
0.001703422,154.2549805
0.001709126,154.3405368
0.001714069,154.4262025
0.001718632,154.5119229
0.001723194,154.5976433
0.001727757,154.6833638
0.00173232,154.7690842
0.001736882,154.8548047
0.001741445,154.9405251
0.001746008,155.0262455
0.00175057,155.111966
0.001755133,155.1976864
0.001761217,155.2831879
0.001768061,155.3685799
0.001774905,155.453972
0.001781749,155.539364
0.001788593,155.624756
0.001795437,155.710148
0.001802281,155.79554
0.001809125,155.8809321
0.00181597,155.9663241
0.001822814,156.0517161
0.001828137,156.1373271
0.0018327,156.2230475
0.001837262,156.3087679
0.001841825,156.3944884
0.001846388,156.4802088
0.00185095,156.5659293
0.001855513,156.6516497
0.001860076,156.7373701
0.001864638,156.8230906
0.001869201,156.908811
0.001874524,156.994422
0.001880228,157.0799782
0.001885931,157.1655344
0.001891635,157.2510907
0.001897338,157.3366469
0.001903042,157.4222031
0.001908745,157.5077594
0.001914449,157.5933156
0.001920152,157.6788718
0.001925856,157.7644281
0.001931559,157.8499843
0.001937263,157.9355405
0.001942966,158.0210967
0.001948669,158.106653
0.001954373,158.1922092
0.001960076,158.2777654
0.00196578,158.3633217
0.001971483,158.4488779
0.001977186,158.5344341
0.00198289,158.6199904
0.001987833,158.7056561
0.001992396,158.7913765
0.001996958,158.877097
0.002001521,158.9628174
0.002006084,159.0485379
0.002010646,159.1342583
0.002015209,159.2199788
0.002019772,159.3056992
0.002024334,159.3914197
0.002028897,159.4771401
0.00203422,159.5339586
0.002039924,159.5763262
0.002045627,159.6186938
0.00205133,159.6610614
0.002057034,159.7034289
0.002062737,159.7457965
0.002068441,159.7881641
0.002074144,159.8305316
0.002079847,159.8728992
0.002085551,159.9152668
0.002091254,159.9864268
0.002096958,160.071983
0.002102661,160.1575392
0.002108365,160.2430955
0.002114068,160.3286517
0.002119772,160.4142079
0.002125475,160.4997642
0.002131179,160.5853204
0.002136882,160.6708766
0.002142586,160.7564329
0.00214905,160.8130872
0.002155894,160.8552905
0.002162738,160.8974939
0.002169582,160.9396973
0.002176426,160.9819006
0.00218327,161.024104
0.002190114,161.0663073
0.002196958,161.1085107
0.002203803,161.1507141
0.002210647,161.1929174
0.00221673,161.2352303
0.002222434,161.2775978
0.002228137,161.3199654
0.00223384,161.362333
0.002239544,161.4047006
0.002245247,161.4470682
0.002250951,161.4894357
0.002256654,161.5318033
0.002262357,161.5741709
0.002268061,161.6165385
0.002273764,161.6589061
0.002279468,161.7012736
0.002285171,161.7436412
0.002290874,161.7860088
0.002296578,161.8283764
0.002302281,161.870744
0.002307985,161.9131115
0.002313688,161.9554791
0.002319391,161.9978467
0.002325095,162.0402143
0.002331559,162.1112648
0.002338403,162.1966568
0.002345247,162.2820488
0.002352091,162.3674408
0.002358935,162.4528328
0.002365779,162.5382249
0.002372623,162.6236169
0.002379467,162.7090089
0.002386312,162.7944009
0.002393156,162.8797929
0.0024,162.9363925
0.002406844,162.9785958
0.002413688,163.0207992
0.002420532,163.0630026
0.002427376,163.1052059
0.00243422,163.1474093
0.002441064,163.1896126
0.002447908,163.231816
0.002454753,163.2740194
0.002461597,163.3162227
0.002468441,163.3872185
0.002475285,163.4726105
0.002482129,163.5580025
0.002488973,163.6433945
0.002495817,163.7287865
0.002502661,163.8141786
0.002509505,163.8995706
0.002516349,163.9849626
0.002523194,164.0703546
0.002530038,164.1557466
0.002536882,164.2123462
0.002543726,164.2545496
0.00255057,164.2967529
0.002557414,164.3389563
0.002564258,164.3811597
0.002571102,164.423363
0.002577946,164.4655664
0.00258479,164.5077698
0.002591635,164.5499731
0.002598479,164.5921765
0.002606844,164.6629534
0.002615969,164.7480169
0.002625095,164.8330805
0.00263422,164.9181441
0.002643346,165.0032077
0.002652471,165.0882713
0.002661597,165.1733348
0.002670722,165.2583984
0.002679848,165.343462
0.002688973,165.4285256
0.002697338,165.4849062
0.002705323,165.5269453
0.002713308,165.5689845
0.002721293,165.6110236
0.002729277,165.6530628
0.002737262,165.6951019
0.002745247,165.737141
0.002753232,165.7791802
0.002761217,165.8212193
0.002769201,165.8632585
0.002775665,165.9055166
0.002781369,165.9478841
0.002787072,165.9902517
0.002792775,166.0326193
0.002798479,166.0749869
0.002804182,166.1173545
0.002809886,166.159722
0.002815589,166.2020896
0.002821292,166.2444572
0.002826996,166.2868248
0.00283346,166.3578753
0.002840304,166.4432673
0.002847148,166.5286593
0.002853992,166.6140513
0.002860836,166.6994433
0.00286768,166.7848354
0.002874524,166.8702274
0.002881368,166.9556194
0.002888213,167.0410114
0.002895057,167.1264034
0.002903422,167.1539916
0.002912547,167.1526779
0.002921673,167.1513641
0.002930798,167.1500504
0.002939924,167.1487367
0.002949049,167.147423
0.002958175,167.1461093
0.0029673,167.1447955
0.002976426,167.1434818
0.002985551,167.1421681
0.002993156,167.1698658
0.003,167.2120691
0.003006844,167.2542725
0.003013688,167.2964759
0.003020532,167.3386792
0.003027376,167.3808826
0.00303422,167.4230859
0.003041064,167.4652893
0.003047909,167.5074927
0.003054753,167.549696
0.003063118,167.5916804
0.003072243,167.6335554
0.003081369,167.6754303
0.003090494,167.7173052
0.00309962,167.7591801
0.003108745,167.8010551
0.003117871,167.84293
0.003126996,167.8848049
0.003136122,167.9266799
0.003145247,167.9685548
0.003152852,168.0106487
0.003159696,168.052852
0.00316654,168.0950554
0.003173384,168.1372588
0.003180228,168.1794621
0.003187072,168.2216655
0.003193916,168.2638688
0.00320076,168.3060722
0.003207605,168.3482756
0.003214449,168.3904789
0.003221293,168.4326823
0.003228137,168.4748856
0.003234981,168.517089
0.003241825,168.5592924
0.003248669,168.6014957
0.003255513,168.6436991
0.003262357,168.6859024
0.003269201,168.7281058
0.003276046,168.7703092
0.00328289,168.8125125
0.003290494,168.8546064
0.003298479,168.8966456
0.003306464,168.9386847
0.003314449,168.9807239
0.003322433,169.022763
0.003330418,169.0648022
0.003338403,169.1068413
0.003346388,169.1488805
0.003354373,169.1909196
0.003362357,169.2329588
0.003368821,169.2464244
0.003374525,169.2456033
0.003380228,169.2447823
0.003385931,169.2439612
0.003391635,169.2431401
0.003397338,169.242319
0.003403042,169.2414979
0.003408745,169.2406769
0.003414448,169.2398558
0.003420152,169.2390347
0.003425855,169.2670061
0.003431559,169.3093736
0.003437262,169.3517412
0.003442965,169.3941088
0.003448669,169.4364764
0.003454372,169.478844
0.003460076,169.5212115
0.003465779,169.5635791
0.003471482,169.6059467
0.003477186,169.6483143
0.00348441,169.6616705
0.003492395,169.660521
0.00350038,169.6593714
0.003508365,169.6582219
0.003516349,169.6570724
0.003524334,169.6559229
0.003532319,169.6547734
0.003540304,169.6536239
0.003548289,169.6524744
0.003556273,169.6513249
0.003565019,169.6788583
0.003574144,169.7207333
0.00358327,169.7626082
0.003592395,169.8044831
0.003601521,169.846358
0.003610646,169.888233
0.003619772,169.9301079
0.003628897,169.9719828
0.003638023,170.0138578
0.003647148,170.0557327
0.003656274,170.0976076
0.003665399,170.1394826
0.003674525,170.1813575
0.00368365,170.2232324
0.003692776,170.2651073
0.003701901,170.3069823
0.003711027,170.3488572
0.003720152,170.3907321
0.003729278,170.4326071
0.003738403,170.474482
0.003746008,170.4877834
0.003752852,170.4867982
0.003759696,170.4858129
0.00376654,170.4848276
0.003773384,170.4838423
0.003780228,170.482857
0.003787072,170.4818717
0.003793916,170.4808864
0.003800761,170.4799011
0.003807605,170.4789158
0.003815209,170.5066135
0.003823194,170.5486526
0.003831179,170.5906918
0.003839164,170.6327309
0.003847148,170.6747701
0.003855133,170.7168092
0.003863118,170.7588483
0.003871103,170.8008875
0.003879088,170.8429266
0.003887072,170.8849658
0.003895057,170.9270049
0.003903042,170.9690441
0.003911027,171.0110832
0.003919012,171.0531224
0.003926996,171.0951615
0.003934981,171.1372007
0.003942966,171.1792398
0.003950951,171.221279
0.003958936,171.2633181
0.00396692,171.3053573
0.003974145,171.3475059
0.003980989,171.3897092
0.003987833,171.4319126
0.003994677,171.474116
0.004001521,171.5163193
0.004008365,171.5585227
0.004015209,171.600726
0.004022053,171.6429294
0.004028898,171.6851328
0.004035742,171.7273361
0.004043346,171.76943
0.004051331,171.8114691
0.004059316,171.8535083
0.004067301,171.8955474
0.004075285,171.9375866
0.00408327,171.9796257
0.004091255,172.0216648
0.00409924,172.063704
0.004107225,172.1057431
0.004115209,172.1477823
0.004124715,172.16081
0.004134981,172.1593321
0.004145247,172.1578542
0.004155513,172.1563762
0.004165779,172.1548983
0.004176046,172.1534204
0.004186312,172.1519424
0.004196578,172.1504645
0.004206844,172.1489866
0.00421711,172.1475086
0.004225855,172.2038345
0.00423384,172.2890623
0.004241825,172.3742901
0.00424981,172.4595179
0.004257794,172.5447457
0.004265779,172.6299735
0.004273764,172.7152013
0.004281749,172.8004291
0.004289734,172.8856568
0.004297718,172.9708846
0.004307985,172.9981991
0.004319392,172.996557
0.004330798,172.9949148
0.004342205,172.9932727
0.004353612,172.9916305
0.004365019,172.9899884
0.004376426,172.9883462
0.004387833,172.9867041
0.00439924,172.9850619
0.004410647,172.9834198
0.004421293,173.039472
0.004431559,173.1243714
0.004441825,173.2092707
0.004452091,173.2941701
0.004462357,173.3790695
0.004472624,173.4639688
0.00448289,173.5488682
0.004493156,173.6337676
0.004503422,173.7186669
0.004513688,173.8035663
0.004524715,173.8307713
0.004536122,173.8291292
0.004547528,173.827487
0.004558935,173.8258448
0.004570342,173.8242027
0.004581749,173.8225605
0.004593156,173.8209184
0.004604563,173.8192762
0.00461597,173.817634
0.004627377,173.8159919
0.004638784,173.8719346
0.00465019,173.9566698
0.004661597,174.0414049
0.004673004,174.1261401
0.004684411,174.2108752
0.004695818,174.2956104
0.004707224,174.3803456
0.004718631,174.4650807
0.004730038,174.5498159
0.004741445,174.634551
0.00474981,174.6621392
0.004756654,174.6611539
0.004763498,174.6601686
0.004770342,174.6591833
0.004777186,174.658198
0.00478403,174.6572127
0.004790874,174.6562274
0.004797718,174.6552421
0.004804563,174.6542568
0.004811407,174.6532715
0.004818251,174.7098711
0.004825095,174.7952631
0.004831939,174.8806552
0.004838783,174.9660472
0.004845627,175.0514392
0.004852471,175.1368312
0.004859315,175.2222232
0.004866159,175.3076153
0.004873004,175.3930073
0.004879848,175.4783993
0.004889734,175.5057685
0.004901141,175.5041264
0.004912547,175.5024842
0.004923954,175.500842
0.004935361,175.4991999
0.004946768,175.4975577
0.004958175,175.4959156
0.004969582,175.4942734
0.004980989,175.4926312
0.004992396,175.4909891
0.005000761,175.5473697
0.005007605,175.6327617
0.005014449,175.7181538
0.005021293,175.8035458
0.005028137,175.8889378
0.005034981,175.9743298
0.005041825,176.0597218
0.005048669,176.1451139
0.005055514,176.2305059
0.005062358,176.3158979
0.005069202,176.343705
0.005076046,176.3427197
0.00508289,176.3417344
0.005089734,176.3407491
0.005096578,176.3397638
0.005103422,176.3387785
0.005110266,176.3377932
0.00511711,176.3368079
0.005123955,176.3358226
0.005130799,176.3348373
0.005138403,176.362535
0.005146388,176.4045742
0.005154373,176.4466133
0.005162358,176.4886525
0.005170342,176.5306916
0.005178327,176.5727308
0.005186312,176.6147699
0.005194297,176.6568091
0.005202282,176.6988482
0.005210266,176.7408874
0.005218251,176.7829265
0.005226236,176.8249657
0.005234221,176.8670048
0.005242206,176.9090439
0.00525019,176.9510831
0.005258175,176.9931223
0.00526616,177.0351614
0.005274145,177.0772006
0.00528213,177.1192397
0.005290114,177.1612789
0.00529886,177.2032085
0.005307985,177.2450834
0.00531711,177.2869584
0.005326236,177.3288333
0.005335361,177.3707082
0.005344487,177.4125832
0.005353612,177.4544581
0.005362737,177.496333
0.005371863,177.538208
0.005380988,177.5800829
0.005389353,177.6220673
0.005397338,177.6641064
0.005405323,177.7061456
0.005413308,177.7481847
0.005421292,177.7902239
0.005429277,177.832263
0.005437262,177.8743021
0.005445247,177.9163413
0.005453232,177.9583804
0.005461216,178.0004196
0.005469201,178.0424587
0.005477186,178.0844979
0.005485171,178.126537
0.005493156,178.1685761
0.00550114,178.2106153
0.005509125,178.2526545
0.00551711,178.2946936
0.005525095,178.3367327
0.00553308,178.3787719
0.005541064,178.4208111
0.00555057,178.4626312
0.005560836,178.504342
0.005571103,178.5460527
0.005581369,178.5877634
0.005591635,178.6294741
0.005601901,178.6711848
0.005612167,178.7128955
0.005622434,178.7546062
0.0056327,178.7963169
0.005642966,178.8380276
0.005651711,178.8799573
0.005659696,178.9219965
0.005667681,178.9640356
0.005675666,179.0060747
0.00568365,179.0481139
0.005691635,179.0901531
0.00569962,179.1321922
0.005707605,179.1742313
0.00571559,179.2162705
0.005723574,179.2583097
0.005731559,179.2715564
0.005739544,179.2704069
0.005747529,179.2692573
0.005755514,179.2681078
0.005763498,179.2669583
0.005771483,179.2658088
0.005779468,179.2646593
0.005787453,179.2635098
0.005795438,179.2623603
0.005803422,179.2612108
0.005811407,179.2600613
0.005819392,179.2589118
0.005827377,179.2577622
0.005835362,179.2566127
0.005843346,179.2554632
0.005851331,179.2543137
0.005859316,179.2531642
0.005867301,179.2520147
0.005875286,179.2508652
0.00588327,179.2497157
0.005888974,179.277687
0.005893537,179.3202188
0.005898099,179.3627506
0.005902662,179.4052824
0.005907225,179.4478142
0.005911787,179.490346
0.00591635,179.5328778
0.005920913,179.5754096
0.005925475,179.6179413
0.005930038,179.6604731
0.005935361,179.674103
0.005941065,179.6732819
0.005946768,179.6724609
0.005952471,179.6716398
0.005958175,179.6708187
0.005963878,179.6699976
0.005969582,179.6691765
0.005975285,179.6683555
0.005980988,179.6675344
0.005986692,179.6667133