File: data/Brass_grainsize_0_025mm.csv
Strain,Stress (MPa)
0,0
1.47E-06,0.164823581
2.93E-06,0.329647163
4.40E-06,0.494470744
5.86E-06,0.659294325
7.33E-06,0.824117906
8.80E-06,0.988941488
1.03E-05,1.153765069
1.17E-05,1.31858865
1.32E-05,1.483412232
1.47E-05,1.648235813
1.61E-05,1.813059394
1.76E-05,1.977882976
1.91E-05,2.142706557
2.05E-05,2.307530138
2.20E-05,2.472353719
2.32E-05,2.655549134
2.40E-05,2.875488215
2.47E-05,3.095427296
2.54E-05,3.315366377
2.62E-05,3.535305457
2.69E-05,3.755244538
2.77E-05,3.975183619
2.84E-05,4.1951227
2.91E-05,4.415061781
2.99E-05,4.635000862
3.06E-05,4.854939943
3.14E-05,5.074879024
3.21E-05,5.294818104
3.28E-05,5.514757185
3.36E-05,5.734696266
3.43E-05,5.954635347
3.51E-05,6.137900484
3.58E-05,6.302828649
3.65E-05,6.467756813
3.73E-05,6.632684978
3.80E-05,6.797613143
3.88E-05,6.962541308
3.95E-05,7.127469472
4.02E-05,7.292397637
4.10E-05,7.457325802
4.17E-05,7.622253967
4.24E-05,7.787182131
4.32E-05,7.952110296
4.39E-05,8.117038461
4.47E-05,8.281966626
4.54E-05,8.44689479
4.61E-05,8.611822955
4.76E-05,8.804151994
4.91E-05,8.996481033
5.05E-05,9.188810072
5.20E-05,9.381139111
5.35E-05,9.57346815
5.49E-05,9.765797189
5.64E-05,9.958126228
5.79E-05,10.15045527
5.93E-05,10.34278431
6.08E-05,10.53511335
6.23E-05,10.72744238
6.37E-05,10.91977142
6.52E-05,11.11210046
6.67E-05,11.3044295
6.81E-05,11.49675854
6.96E-05,11.70742455
7.11E-05,11.95476451
7.26E-05,12.20210446
7.40E-05,12.44944442
7.55E-05,12.69678437
7.70E-05,12.94412433
7.84E-05,13.19146429
7.99E-05,13.43880424
8.14E-05,13.6861442
8.29E-05,13.93348415
8.43E-05,14.18082411
8.58E-05,14.42816407
8.73E-05,14.67550402
8.87E-05,14.92284398
9.02E-05,15.17018393
9.17E-05,15.41752389
9.32E-05,15.66486384
9.46E-05,15.9122038
9.61E-05,16.15954375
9.76E-05,16.40688371
9.90E-05,16.65422366
0.000100505,16.90156362
0.000101976,17.14890357
0.000103447,17.39624353
0.000104917,17.64358348
0.000106388,17.89092344
0.000107859,18.13826339
0.00010933,18.38560335
0.000110801,18.6329433
0.000112271,18.88028326
0.000113742,19.12762321
0.000115213,19.37496317
0.000116685,19.64980858
0.000118158,19.924654
0.00011963,20.19949941
0.000121103,20.47434482
0.000122575,20.74919024
0.000124048,21.02403565
0.00012552,21.29888107
0.000126992,21.57372648
0.000128465,21.84857189
0.000129937,22.12341731
0.00013141,22.39826272
0.000132882,22.67310813
0.000134355,22.94795355
0.000135827,23.22279896
0.000137299,23.49764437
0.000138771,23.7633213
0.000140242,24.01066126
0.000141713,24.25800121
0.000143184,24.50534117
0.000144655,24.75268112
0.000146125,25.00002108
0.000147596,25.24736104
0.000149067,25.49470099
0.000150538,25.74204095
0.000152009,25.9893809
0.00015348,26.23672086
0.00015495,26.48406082
0.000156421,26.73140077
0.000157892,26.97874073
0.000159363,27.22608068
0.000160834,27.47342064
0.000162306,27.73909757
0.000163778,28.01394298
0.00016525,28.28878839
0.000166723,28.5636338
0.000168195,28.83847922
0.000169668,29.11332463
0.00017114,29.38817004
0.000172613,29.66301546
0.000174085,29.93786087
0.000175557,30.21270628
0.00017703,30.4875517
0.000178502,30.76239711
0.000179975,31.03724252
0.000181447,31.31208793
0.00018292,31.58693335
0.000184392,31.86177876
0.000185864,32.13662417
0.000187337,32.41146959
0.000188809,32.686315
0.000190282,32.96116041
0.000191754,33.23600583
0.000193227,33.51085124
0.000194699,33.78569666
0.000196171,34.06054207
0.000197644,34.33538748
0.000199116,34.6102329
0.000200589,34.88507831
0.000202061,35.15992372
0.000203534,35.43476914
0.000205006,35.70961455
0.000206478,35.98445996
0.00020795,36.24096841
0.000209419,36.4608029
0.000210888,36.6806374
0.000212357,36.9004719
0.000213826,37.12030639
0.000215296,37.34014089
0.000216765,37.55997539
0.000218234,37.77980989
0.000219703,37.99964438
0.000221172,38.21947888
0.000222641,38.43931338
0.000224111,38.65914788
0.00022558,38.87898237
0.000227049,39.09881687
0.000228518,39.31865137
0.000229987,39.53848586
0.000231456,39.75832036
0.000232926,39.97815486
0.000234395,40.19798936
0.000235864,40.41782386
0.000237333,40.63765835
0.000238803,40.85749285
0.000240272,41.07732735
0.000241741,41.29716185
0.00024321,41.51699634
0.00024468,41.73683084
0.000246149,41.95666534
0.000247618,42.17649984
0.000249087,42.39633434
0.000250557,42.61616883
0.000252026,42.83600333
0.000253495,43.05583783
0.000254969,43.3581887
0.000256443,43.66053957
0.000257917,43.96289044
0.000259391,44.26524132
0.000260865,44.56759219
0.000262339,44.86994306
0.000263813,45.17229393
0.000265287,45.4746448
0.000266761,45.77699567
0.000268235,46.07934654
0.000269709,46.38169742
0.000271183,46.68404829
0.000272657,46.98639916
0.000274131,47.28875003
0.000275605,47.5911009
0.000277078,47.8751148
0.000278549,48.12245476
0.00028002,48.36979471
0.000281491,48.61713467
0.000282962,48.86447462
0.000284432,49.11181458
0.000285903,49.35915453
0.000287374,49.60649449
0.000288845,49.85383444
0.000290316,50.1011744
0.000291787,50.34851435
0.000293257,50.59585431
0.000294728,50.84319426
0.000296199,51.09053422
0.00029767,51.33787417
0.000299141,51.58521413
0.000301586,51.88742555
0.000304517,52.21707272
0.000307449,52.54671988
0.000310381,52.87636704
0.000313313,53.2060142
0.000316245,53.53566137
0.000319177,53.86530853
0.000322108,54.19495569
0.00032504,54.52460285
0.000327972,54.85425002
0.000330904,55.18389718
0.000333836,55.51354434
0.000336768,55.8431915
0.000339699,56.17283867
0.000342631,56.50248583
0.000345563,56.83213299
0.000346309,57.13458845
0.000347055,57.4370439
0.000347801,57.73949936
0.000348547,58.04195481
0.000349293,58.34441027
0.000350039,58.64686572
0.000350785,58.94932118
0.000351531,59.25177663
0.000352277,59.55423209
0.000353023,59.85668754
0.000353769,60.159143
0.000354515,60.46159845
0.000355261,60.76405391
0.000356007,61.06650936
0.000356753,61.36896482
0.000357983,61.65301358
0.000360182,61.90024895
0.000362381,62.14748432
0.00036458,62.3947197
0.000366779,62.64195507
0.000368978,62.88919044
0.000371177,63.13642581
0.000373376,63.38366118
0.000375574,63.63089656
0.000377773,63.87813193
0.000379972,64.1253673
0.000382171,64.37260267
0.00038437,64.61983804
0.000386569,64.86707342
0.000388768,65.11430879
0.000390967,65.36154416
0.000392678,65.57217531
0.000394146,65.76450435
0.000395613,65.95683339
0.000397081,66.14916243
0.000398548,66.34149147
0.000400016,66.53382051
0.000401483,66.72614955
0.000402951,66.91847859
0.000404418,67.11080762
0.000405886,67.30313666
0.000407353,67.4954657
0.000408821,67.68779474
0.000410288,67.88012378
0.000411756,68.07245282
0.000413223,68.26478186
0.000414691,68.4571109
0.000415434,68.70455544
0.000416176,68.95199998
0.000416919,69.19944452
0.000417662,69.44688906
0.000418405,69.69433359
0.000419147,69.94177813
0.00041989,70.18922267
0.000420633,70.43666721
0.000421376,70.68411175
0.000422118,70.93155629
0.000422861,71.17900083
0.000423604,71.42644537
0.000424346,71.67388991
0.000425089,71.92133445
0.000425832,72.16877898
0.000427059,72.40698531
0.000429257,72.62671523
0.000431454,72.84644514
0.000433651,73.06617506
0.000435849,73.28590497
0.000438046,73.50563488
0.000440243,73.7253648
0.00044244,73.94509471
0.000444638,74.16482463
0.000446835,74.38455454
0.000449032,74.60428446
0.000451229,74.82401437
0.000453427,75.04374428
0.000455624,75.2634742
0.000457821,75.48320411
0.000460019,75.70293403
0.00046076,75.92287311
0.000460773,76.14291677
0.000460786,76.36296043
0.000460799,76.5830041
0.000460812,76.80304776
0.000460825,77.02309143
0.000460838,77.24313509
0.000460851,77.46317876
0.000460864,77.68322242
0.000460877,77.90326608
0.00046089,78.12330975
0.000460903,78.34335341
0.000460916,78.56339708
0.000460929,78.78344074
0.000460942,79.00348441
0.000460955,79.22352807
0.000463152,79.44325798
0.00046535,79.6629879
0.000467547,79.88271781
0.000469744,80.10244773
0.000471941,80.32217764
0.000474139,80.54190755
0.000476336,80.76163747
0.000478533,80.98136738
0.00048073,81.2010973
0.000482928,81.42082721
0.000485125,81.64055712
0.000487322,81.86028704
0.00048952,82.08001695
0.000491717,82.29974687
0.000493914,82.51947678
0.000496113,82.76671215
0.000498315,83.06895844
0.000500517,83.37120473
0.000502719,83.67345102
0.000504922,83.9756973
0.000507124,84.27794359
0.000509326,84.58018988
0.000511528,84.88243617
0.00051373,85.18468245
0.000515932,85.48692874
0.000518134,85.78917503
0.000520336,86.09142132
0.000522539,86.3936676
0.000524741,86.69591389
0.000526943,86.99816018
0.000529145,87.30040647
0.000530863,87.62105945
0.000532338,87.95091578
0.000533814,88.28077211
0.00053529,88.61062844
0.000536766,88.94048477
0.000538241,89.2703411
0.000539717,89.60019743
0.000541193,89.93005376
0.000542668,90.25991008
0.000544144,90.58976641
0.00054562,90.91962274
0.000547095,91.24947907
0.000548571,91.5793354
0.000550047,91.90919173
0.000551522,92.23904806
0.000552998,92.56890439
0.000555931,92.92605701
0.000558865,93.28320963
0.000561798,93.64036225
0.000564732,93.99751487
0.000567665,94.35466749
0.000570599,94.71182012
0.000573532,95.06897274
0.000576466,95.42612536
0.000579399,95.78327798
0.000582333,96.1404306
0.000585266,96.49758322
0.0005882,96.85473584
0.000591133,97.21188846
0.000594067,97.56904108
0.000597,97.9261937
0.000599447,98.25591059
0.000600919,98.530756
0.000602392,98.80560141
0.000603864,99.08044682
0.000605337,99.35529223
0.000606809,99.63013765
0.000608281,99.90498306
0.000609754,100.1798285
0.000611226,100.4546739
0.000612699,100.7295193
0.000614171,101.0043647
0.000615643,101.2792101
0.000617116,101.5540555
0.000618588,101.8289009
0.000620061,102.1037464
0.000621533,102.3785918
0.000623975,102.6349608
0.000626902,102.8820915
0.000629829,103.1292223
0.000632756,103.3763531
0.000635683,103.6234839
0.00063861,103.8706147
0.000641537,104.1177455
0.000644464,104.3648763
0.000647391,104.6120071
0.000650318,104.8591379
0.000653245,105.1062687
0.000656172,105.3533994
0.000659099,105.6005302
0.000662026,105.847661
0.000664953,106.0947918
0.00066788,106.3419226
0.000672263,106.5888442
0.000676646,106.8357658
0.00068103,107.0826875
0.000685413,107.3296091
0.000689796,107.5765307
0.000694179,107.8234523
0.000698562,108.0703739
0.000702946,108.3172956
0.000707329,108.5642172
0.000711712,108.8111388
0.000716095,109.0580604
0.000720478,109.304982
0.000724861,109.5519036
0.000729245,109.7988253
0.000733628,110.0457469
0.000737524,110.2652328
0.000740446,110.4298472
0.000743368,110.5944616
0.00074629,110.759076
0.000749213,110.9236904
0.000752135,111.0883049
0.000755057,111.2529193
0.000757979,111.4175337
0.000760901,111.5821481
0.000763823,111.7467625
0.000766745,111.9113769
0.000769667,112.0759914
0.00077259,112.2406058
0.000775512,112.4052202
0.000778434,112.5698346
0.000781356,112.734449
0.000784276,112.8623895
0.000787195,112.971993
0.000790114,113.0815965
0.000793033,113.1912
0.000795951,113.3008035
0.00079887,113.410407
0.000801789,113.5200105
0.000804708,113.629614
0.000807627,113.7392175
0.000810546,113.848821
0.000813465,113.9584245
0.000816384,114.068028
0.000819302,114.1776315
0.000822221,114.287235
0.00082514,114.3968385
0.000828059,114.506442
0.000832437,114.6708472
0.000836816,114.8352525
0.000841194,114.9996577
0.000845572,115.164063
0.00084995,115.3284682
0.000854329,115.4928735
0.000858707,115.6572787
0.000863085,115.821684
0.000867463,115.9860892
0.000871842,116.1504945
0.00087622,116.3148997
0.000880598,116.479305
0.000884977,116.6437102
0.000889355,116.8081155
0.000893733,116.9725207
0.000898111,117.1277575
0.000902488,117.2646573
0.000906864,117.401557
0.000911241,117.5384568
0.000915618,117.6753566
0.000919994,117.8122564
0.000924371,117.9491562
0.000928748,118.086056
0.000933124,118.2229558
0.000937501,118.3598556
0.000941878,118.4967554
0.000946254,118.6336552
0.000950631,118.770555
0.000955008,118.9074548
0.000959384,119.0443545
0.000963761,119.1812543
0.000969111,119.3546886
0.000974947,119.5463902
0.000980783,119.7380917
0.000986619,119.9297932
0.000992455,120.1214948
0.000998291,120.3131963
0.001004127,120.5048979
0.001009963,120.6965994
0.001015799,120.8883009
0.001021635,121.0800025
0.001027472,121.271704
0.001033308,121.4634055
0.001039144,121.6551071
0.00104498,121.8468086
0.001050816,122.0385102
0.001056652,122.2302117
0.001061755,122.3395014
0.001066858,122.4487912
0.001071961,122.5580809
0.001077065,122.6673707
0.001082168,122.7766604
0.001087271,122.8859502
0.001092374,122.9952399
0.001097477,123.1045297
0.00110258,123.2138194
0.001107683,123.3231091
0.001112786,123.4323989
0.00111789,123.5416886
0.001122993,123.6509784
0.001128096,123.7602681
0.001133199,123.8695579
0.001139274,123.9970451
0.001147293,124.1609275
0.001155311,124.3248098
0.00116333,124.4886921
0.001171349,124.6525745
0.001179368,124.8164568
0.001187386,124.9803391
0.001195405,125.1442214
0.001203424,125.3081038
0.001211443,125.4719861
0.001219461,125.6358684
0.00122748,125.7997507
0.001235499,125.9636331
0.001243518,126.1275154
0.001251536,126.2913977
0.001259555,126.4552801
0.001267086,126.5825582
0.001274374,126.6915342
0.001281661,126.8005102
0.001288948,126.9094862
0.001296236,127.0184622
0.001303523,127.1274382
0.001310811,127.2364142
0.001318098,127.3453902
0.001325385,127.4543662
0.001332673,127.5633422
0.00133996,127.6723182
0.001347247,127.7812942
0.001354535,127.8902702
0.001361822,127.9992462
0.00136911,128.1082222
0.001376397,128.2171982
0.001382228,128.3263834
0.001388059,128.4355685
0.001393891,128.5447537
0.001399722,128.6539388
0.001405553,128.763124
0.001411384,128.8723092
0.001417216,128.9814943
0.001423047,129.0906795
0.001428878,129.1998646
0.001434709,129.3090498
0.001440541,129.418235
0.001446372,129.5274201
0.001452203,129.6366053
0.001458034,129.7457904
0.001463866,129.8549756
0.001470182,129.9549225
0.001477467,130.0363931
0.001484753,130.1178636
0.001492039,130.1993342
0.001499325,130.2808047
0.001506611,130.3622752
0.001513896,130.4437458
0.001521182,130.5252163
0.001528468,130.6066869
0.001535754,130.6881574
0.001543039,130.769628
0.001550325,130.8510985
0.001557611,130.932569
0.001564897,131.0140396
0.001572183,131.0955101
0.001579468,131.1769807
0.001585782,131.2402537
0.00159161,131.2944279
0.001597438,131.3486022
0.001603266,131.4027764
0.001609094,131.4569507
0.001614922,131.5111249
0.00162075,131.5652992
0.001626578,131.6194734
0.001632406,131.6736477
0.001638234,131.7278219
0.001644062,131.7819962
0.00164989,131.8361704
0.001655718,131.8903447
0.001661546,131.9445189
0.001667374,131.9986932
0.001673202,132.0528674
0.001677574,132.1072508
0.001681946,132.1616342
0.001686317,132.2160176
0.001690689,132.2704011
0.001695061,132.3247845
0.001699433,132.3791679
0.001703804,132.4335513
0.001708176,132.4879347
0.001712548,132.5423181
0.00171692,132.5967015
0.001721291,132.6510849
0.001725663,132.7054684
0.001730035,132.7598518
0.001734407,132.8142352
0.001738778,132.8686186
0.001744121,132.9228626
0.001751405,132.9768276
0.001758689,133.0307927
0.001765974,133.0847578
0.001773258,133.1387229
0.001780542,133.192688
0.001787826,133.2466531
0.00179511,133.3006182
0.001802395,133.3545832
0.001809679,133.4085483
0.001816963,133.4625134
0.001824247,133.5164785
0.001831531,133.5704436
0.001838816,133.6244087
0.0018461,133.6783738
0.001853384,133.7323388
0.001859697,133.7864434
0.001865525,133.8406176
0.001871353,133.8947919
0.001877181,133.9489661
0.001883009,134.0031404
0.001888837,134.0573146
0.001894665,134.1114889
0.001900493,134.1656631
0.001906321,134.2198374
0.001912149,134.2740116
0.001917976,134.3281859
0.001923804,134.3823601
0.001929632,134.4365344
0.00193546,134.4907086
0.001941288,134.5448829
0.001947116,134.5990571
0.001954399,134.6255167
0.001961681,134.6519763
0.001968964,134.678436
0.001976246,134.7048956
0.001983529,134.7313552
0.001990811,134.7578148
0.001998094,134.7842745
0.002005376,134.8107341
0.002012659,134.8371937
0.002019941,134.8636533
0.002027224,134.890113
0.002034506,134.9165726
0.002041789,134.9430322
0.002049071,134.9694918
0.002056354,134.9959515
0.002062666,135.0225505
0.002067036,135.0494285
0.002071406,135.0763064
0.002075776,135.1031844
0.002080146,135.1300623
0.002084517,135.1569403
0.002088887,135.1838183
0.002093257,135.2106962
0.002097627,135.2375742
0.002101997,135.2644521
0.002106367,135.2913301
0.002110738,135.3182081
0.002115108,135.345086
0.002119478,135.371964
0.002123848,135.3988419
0.002128218,135.4257199
0.002134531,135.4706559
0.002141815,135.524621
0.0021491,135.5785861
0.002156384,135.6325512
0.002163668,135.6865162
0.002170952,135.7404813
0.002178236,135.7944464
0.00218552,135.8484115
0.002192805,135.9023765
0.002200089,135.9563416
0.002207373,136.0103067
0.002214657,136.0642718
0.002221941,136.1182369
0.002229226,136.1722019
0.00223651,136.226167
0.002243794,136.2801321
0.002251805,136.3064871
0.002259815,136.3328422
0.002267826,136.3591972
0.002275836,136.3855523
0.002283847,136.4119073
0.002291857,136.4382623
0.002299868,136.4646174
0.002307879,136.4909724
0.002315889,136.5173274
0.0023239,136.5436825
0.00233191,136.5700375
0.002339921,136.5963926
0.002347931,136.6227476
0.002355942,136.6491026
0.002363953,136.6754577
0.002371963,136.6926442
0.002379972,136.6914938
0.002387981,136.6903434
0.00239599,136.689193
0.002403999,136.6880426
0.002412008,136.6868921
0.002420017,136.6857417
0.002428026,136.6845913
0.002436035,136.6834409
0.002444044,136.6822905
0.002452053,136.6811401
0.002460062,136.6799896
0.002468071,136.6788392
0.00247608,136.6776888
0.002484089,136.6765384
0.002492098,136.675388
0.002499624,136.7109812
0.002506908,136.7649463
0.002514192,136.8189114
0.002521476,136.8728765
0.002528761,136.9268415
0.002536045,136.9808066
0.002543329,137.0347717
0.002550613,137.0887368
0.002557897,137.1427018
0.002565181,137.1966669
0.002572465,137.250632
0.002579749,137.3045971
0.002587034,137.3585622
0.002594318,137.4125272
0.002601602,137.4664923
0.002608886,137.5204574
0.00261544,137.5470216
0.002621995,137.5735858
0.002628549,137.60015
0.002635104,137.6267142
0.002641658,137.6532784
0.002648213,137.6798427
0.002654767,137.7064069
0.002661321,137.7329711
0.002667876,137.7595353
0.00267443,137.7860995
0.002680985,137.8126637
0.002687539,137.8392279
0.002694094,137.8657921
0.002700648,137.8923563
0.002707202,137.9189205
0.002714,137.9454499
0.002721282,137.9719095
0.002728565,137.9983691
0.002735847,138.0248287
0.00274313,138.0512884
0.002750412,138.077748
0.002757695,138.1042076
0.002764977,138.1306672
0.00277226,138.1571269
0.002779542,138.1835865
0.002786825,138.2100461
0.002794107,138.2365057
0.00280139,138.2629654
0.002808672,138.289425
0.002815955,138.3158846
0.002823237,138.3423442
0.002830036,138.3872105
0.002836592,138.4412802
0.002843148,138.4953499
0.002849704,138.5494195
0.00285626,138.6034892
0.002862816,138.6575589
0.002869372,138.7116285
0.002875928,138.7656982
0.002882484,138.8197679
0.00288904,138.8738375
0.002895597,138.9279072
0.002902153,138.9819768
0.002908709,139.0360465
0.002915265,139.0901162
0.002921821,139.1441858
0.002928377,139.1982555
0.002936386,139.1971051
0.002944395,139.1959547
0.002952404,139.1948042
0.002960413,139.1936538
0.002968422,139.1925034
0.002976431,139.191353
0.00298444,139.1902026
0.002992449,139.1890522
0.003000458,139.1879017
0.003008467,139.1867513
0.003016476,139.1856009
0.003024485,139.1844505
0.003032494,139.1833001
0.003040503,139.1821497
0.003048512,139.1809992
0.003056764,139.1889825
0.003065503,139.2152329
0.003074241,139.2414834
0.00308298,139.2677338
0.003091719,139.2939843
0.003100457,139.3202347
0.003109196,139.3464852
0.003117935,139.3727356
0.003126673,139.3989861
0.003135412,139.4252365
0.003144151,139.451487
0.003152889,139.4777374
0.003161628,139.5039879
0.003170367,139.5302383
0.003179105,139.5564888
0.003187844,139.5827392
0.003196097,139.6090594
0.003204108,139.6354145
0.003212119,139.6617695
0.003220129,139.6881246
0.00322814,139.7144796
0.003236151,139.7408347
0.003244161,139.7671897
0.003252172,139.7935447
0.003260183,139.8198998
0.003268193,139.8462548
0.003276204,139.8726099
0.003284214,139.8989649
0.003292225,139.92532
0.003300236,139.951675
0.003308246,139.9780301
0.003316257,140.0043851
0.003324997,140.058141
0.003333738,140.1118969
0.003342478,140.1656528
0.003351218,140.2194087
0.003359959,140.2731646
0.003368699,140.3269206
0.003377439,140.3806765
0.00338618,140.4344324
0.00339492,140.4881883
0.00340366,140.5419442
0.003412401,140.5957001
0.003421141,140.649456
0.003429881,140.7032119
0.003438622,140.7569678
0.003447362,140.8107237
0.003455859,140.8461775
0.003463868,140.8450271
0.003471877,140.8438767
0.003479886,140.8427263
0.003487895,140.8415759
0.003495904,140.8404254
0.003503913,140.839275
0.003511922,140.8381246
0.00351993,140.8369742
0.003527939,140.8358238
0.003535948,140.8346734
0.003543957,140.8335229
0.003551966,140.8323725
0.003559975,140.8312221
0.003567984,140.8300717
0.003575993,140.8289213
0.003583519,140.8645145
0.003590803,140.9184796
0.003598088,140.9724447
0.003605372,141.0264098
0.003612656,141.0803749
0.00361994,141.1343399
0.003627224,141.188305
0.003634508,141.2422701
0.003641793,141.2962352
0.003649077,141.3502003
0.003656361,141.4041654
0.003663645,141.4581305
0.003670929,141.5120955
0.003678214,141.5660606
0.003685498,141.6200257
0.003692782,141.6739908
0.003700065,141.7004504
0.003707347,141.72691
0.00371463,141.7533697
0.003721912,141.7798293
0.003729195,141.8062889
0.003736477,141.8327485
0.00374376,141.8592082
0.003751042,141.8856678
0.003758325,141.9121274
0.003765607,141.938587
0.00377289,141.9650467
0.003780172,141.9915063
0.003787455,142.0179659
0.003794737,142.0444255
0.00380202,142.0708852
0.003809788,142.0972751
0.003818527,142.1235255
0.003827265,142.149776
0.003836004,142.1760264
0.003844743,142.2022769
0.003853481,142.2285273
0.00386222,142.2547778
0.003870959,142.2810282
0.003879697,142.3072787
0.003888436,142.3335291
0.003897175,142.3597796
0.003905913,142.38603
0.003914652,142.4122805
0.003923391,142.4385309
0.003932129,142.4647814
0.003940868,142.4910318
0.003948637,142.5357587
0.003955921,142.5897238
0.003963205,142.6436889
0.003970489,142.697654
0.003977774,142.751619
0.003985058,142.8055841
0.003992342,142.8595492
0.003999626,142.9135143
0.00400691,142.9674793
0.004014194,143.0214444
0.004021478,143.0754095
0.004028762,143.1293746
0.004036047,143.1833397
0.004043331,143.2373047
0.004050615,143.2912698
0.004057899,143.3452349
0.004067366,143.3713808
0.004076833,143.3975266
0.0040863,143.4236725
0.004095766,143.4498184
0.004105233,143.4759643
0.0041147,143.5021101
0.004124167,143.528256
0.004133634,143.5544019
0.004143101,143.5805478
0.004152568,143.6066936
0.004162034,143.6328395
0.004171501,143.6589854
0.004180968,143.6851313
0.004190435,143.7112771
0.004199902,143.737423
0.004208883,143.7636386
0.004216894,143.7899937
0.004224904,143.8163487
0.004232915,143.8427037
0.004240925,143.8690588
0.004248936,143.8954138
0.004256947,143.9217688
0.004264957,143.9481239
0.004272968,143.9744789
0.004280978,144.000834
0.004288989,144.027189
0.004297,144.053544
0.00430501,144.0798991
0.004313021,144.1062541
0.004321031,144.1326091
0.004329042,144.1589642
0.004337538,144.1852495
0.004346277,144.2115
0.004355015,144.2377504
0.004363754,144.2640009
0.004372493,144.2902513
0.004381232,144.3165018
0.00438997,144.3427523
0.004398709,144.3690027
0.004407448,144.3952532
0.004416187,144.4215036
0.004424925,144.4477541
0.004433664,144.4740046
0.004442403,144.500255
0.004451142,144.5265055
0.00445988,144.5527559
0.004468619,144.5790064
0.004478086,144.6051523
0.004487553,144.6312981
0.004497019,144.657444
0.004506486,144.6835899
0.004515953,144.7097358
0.00452542,144.7358816
0.004534887,144.7620275
0.004544353,144.7881734
0.00455382,144.8143193
0.004563287,144.8404651
0.004572754,144.866611
0.00458222,144.8927569
0.004591687,144.9189028
0.004601154,144.9450486
0.004610621,144.9711945
0.00461936,144.997445
0.004626642,145.0239046
0.004633925,145.0503642
0.004641207,145.0768238
0.00464849,145.1032835
0.004655772,145.1297431
0.004663055,145.1562027
0.004670337,145.1826623
0.00467762,145.209122
0.004684902,145.2355816
0.004692185,145.2620412
0.004699467,145.2885008
0.00470675,145.3149605
0.004714032,145.3414201
0.004721315,145.3678797
0.004728597,145.3943393
0.004737337,145.4389268
0.004746806,145.4925781
0.004756274,145.5462294
0.004765742,145.5998807
0.004775211,145.6535321
0.004784679,145.7071834
0.004794148,145.7608347
0.004803616,145.8144861
0.004813084,145.8681374
0.004822553,145.9217887
0.004832021,145.9754401
0.004841489,146.0290914
0.004850958,146.0827427
0.004860426,146.136394
0.004869895,146.1900454
0.004879363,146.2436967
0.004887374,146.2700517
0.004895384,146.2964068
0.004903395,146.3227618
0.004911406,146.3491169
0.004919416,146.3754719
0.004927427,146.4018269
0.004935437,146.428182
0.004943448,146.454537
0.004951459,146.480892
0.004959469,146.5072471
0.00496748,146.5336021
0.004975491,146.5599572
0.004983501,146.5863122
0.004991512,146.6126672
0.004999523,146.6390223
0.005007534,146.6745458
0.005015546,146.7284063
0.005023558,146.7822668
0.00503157,146.8361273
0.005039583,146.8899878
0.005047595,146.9438483
0.005055607,146.9977088
0.005063619,147.0515693
0.005071632,147.1054298
0.005079644,147.1592903
0.005087656,147.2131508
0.005095668,147.2670113
0.005103681,147.3208718
0.005111693,147.3747323
0.005119705,147.4285928
0.005127717,147.4824533
0.005135728,147.5179768
0.005143739,147.5443319
0.00515175,147.5706869
0.00515976,147.5970419
0.005167771,147.623397
0.005175782,147.649752
0.005183792,147.6761071
0.005191803,147.7024621
0.005199814,147.7288171
0.005207824,147.7551722
0.005215835,147.7815272
0.005223845,147.8078822
0.005231856,147.8342373
0.005239867,147.8605923
0.005247877,147.8869474
0.005255888,147.9133024
0.005263171,147.939762
0.005270453,147.9662216
0.005277736,147.9926813
0.005285018,148.0191409
0.005292301,148.0456005
0.005299583,148.0720601
0.005306866,148.0985198
0.005314148,148.1249794
0.005321431,148.151439
0.005328713,148.1778986
0.005335996,148.2043583
0.005343278,148.2308179
0.005350561,148.2572775
0.005357843,148.2837371
0.005365126,148.3101968
0.005372651,148.3366215
0.005380662,148.3629766
0.005388672,148.3893316
0.005396683,148.4156866
0.005404694,148.4420417
0.005412704,148.4683967
0.005420715,148.4947517
0.005428726,148.5211068
0.005436736,148.5474618
0.005444747,148.5738169
0.005452758,148.6001719
0.005460768,148.6265269
0.005468779,148.652882
0.00547679,148.679237
0.0054848,148.705592
0.005492811,148.7319471
0.005500821,148.7583021
0.005508832,148.7846572
0.005516843,148.8110122
0.005524853,148.8373672
0.005532864,148.8637223
0.005540874,148.8900773
0.005548885,148.9164324
0.005556895,148.9427874
0.005564906,148.9691424
0.005572917,148.9954975
0.005580927,149.0218525
0.005588938,149.0482075
0.005596948,149.0745626
0.005604959,149.1009176
0.005612969,149.1272727
0.00562098,149.1536277
0.005626806,149.1802965
0.005632633,149.2069653
0.005638459,149.2336341
0.005644286,149.2603029
0.005650112,149.2869717
0.005655938,149.3136405
0.005661765,149.3403093
0.005667591,149.366978
0.005673417,149.3936468
0.005679244,149.4203156
0.00568507,149.4469844
0.005690897,149.4736532
0.005696723,149.500322
0.005702549,149.5269908
0.005708376,149.5536596
0.00571493,149.5802238
0.005722941,149.6065789
0.005730951,149.6329339
0.005738962,149.6592889
0.005746972,149.685644
0.005754983,149.711999
0.005762994,149.738354
0.005771004,149.7647091
0.005779015,149.7910641
0.005787025,149.8174192
0.005795036,149.8437742
0.005803047,149.8701292
0.005811057,149.8964843
0.005819068,149.9228393
0.005827078,149.9491943
0.005835089,149.9755494
0.005842614,150.0019741
0.005849897,150.0284338
0.005857179,150.0548934
0.005864462,150.081353
0.005871744,150.1078126
0.005879027,150.1342723
0.005886309,150.1607319
0.005893592,150.1871915
0.005900874,150.2136511
0.005908157,150.2401108
0.005913012,150.2577505