File: data/Brass_grainsize_0_020mm.csv
Strain,Stress (MPa)
0,0
1.64E-06,0.215225354
3.28E-06,0.430450707
4.93E-06,0.645676061
6.57E-06,0.860901414
8.21E-06,1.076126768
9.85E-06,1.291352121
1.15E-05,1.506577475
1.31E-05,1.721802828
1.48E-05,1.937028182
1.64E-05,2.152253535
1.81E-05,2.367478889
1.97E-05,2.582704242
2.13E-05,2.797929596
2.30E-05,3.013154949
2.46E-05,3.351499972
2.63E-05,3.689844995
2.79E-05,4.028190018
2.96E-05,4.366535041
3.12E-05,4.704880064
3.29E-05,5.043225087
3.45E-05,5.38157011
3.62E-05,5.719915132
3.78E-05,6.058260155
3.95E-05,6.396605178
4.11E-05,6.734950201
4.28E-05,7.073295224
4.44E-05,7.411640247
4.61E-05,7.74998527
4.77E-05,7.965210624
4.94E-05,8.180435977
5.10E-05,8.395661331
5.27E-05,8.610886684
5.43E-05,8.826112038
5.59E-05,9.041337391
5.76E-05,9.256562745
5.92E-05,9.471788099
6.09E-05,9.687013452
6.25E-05,9.902238806
6.42E-05,10.11746416
6.58E-05,10.33268951
6.74E-05,10.54791487
6.91E-05,10.76314022
7.07E-05,11.03992541
7.24E-05,11.3167106
7.40E-05,11.59349578
7.57E-05,11.87028097
7.73E-05,12.14706616
7.90E-05,12.42385135
8.06E-05,12.70063654
8.22E-05,12.97742172
8.39E-05,13.25420691
8.55E-05,13.5309921
8.72E-05,13.80777729
8.88E-05,14.08456247
9.05E-05,14.36134766
9.21E-05,14.63813285
9.38E-05,14.91491804
9.54E-05,15.19170323
9.71E-05,15.46848842
9.87E-05,15.7452736
0.000100349,16.02205879
0.000101995,16.29884398
0.000103641,16.57562917
0.000105287,16.85241436
0.000106933,17.12919955
0.000108578,17.40598474
0.000110224,17.68276992
0.00011187,17.95955511
0.000113516,18.2363403
0.000115162,18.51312549
0.000116808,18.78991068
0.000118454,19.06669587
0.0001201,19.34348105
0.000121746,19.62026624
0.000123392,19.89705143
0.000125038,20.17383662
0.000126684,20.45062181
0.000128329,20.72740699
0.000129975,21.00419218
0.000131621,21.28097737
0.000133267,21.55776256
0.000134913,21.83454774
0.000136559,22.11133293
0.000138205,22.38811812
0.000139853,22.69568323
0.0001415,23.00324833
0.000143148,23.31081344
0.000144796,23.61837854
0.000146444,23.92594365
0.000148091,24.23350875
0.000149739,24.54107386
0.000151387,24.84863897
0.000153034,25.15620407
0.000154682,25.46376918
0.00015633,25.77133428
0.000157978,26.07889939
0.000159625,26.38646449
0.000161273,26.6940296
0.000162921,27.00159471
0.000164568,27.30915981
0.000166216,27.61672492
0.000167864,27.92429002
0.000169512,28.23185513
0.000171159,28.53942023
0.000172807,28.84698534
0.000174455,29.15455045
0.000176102,29.46211555
0.00017775,29.76968066
0.000179398,30.07724576
0.000181046,30.38481087
0.000182693,30.69237597
0.000184341,30.99994108
0.000185989,31.30750619
0.000187636,31.61507129
0.000189284,31.9226364
0.000190932,32.2302015
0.00019258,32.53776661
0.000194227,32.84533171
0.000195875,33.15289682
0.000197523,33.46046193
0.00019917,33.76802703
0.000200818,34.07559214
0.000202466,34.38315724
0.000204114,34.69072235
0.000205761,34.99828745
0.000207409,35.30585256
0.000209053,35.55185783
0.000210697,35.7978631
0.000212341,36.04386837
0.000213985,36.28987364
0.000215629,36.53587891
0.000217273,36.78188418
0.000218918,37.02788946
0.000220562,37.27389473
0.000222206,37.5199
0.00022385,37.76590527
0.000225494,38.01191054
0.000227138,38.25791581
0.000228782,38.50392108
0.000230426,38.74992635
0.00023289,39.08815434
0.000235355,39.42638233
0.000237819,39.76461032
0.000240283,40.1028383
0.000242748,40.44106629
0.000245212,40.77929428
0.000247677,41.11752227
0.000250141,41.45575026
0.000252605,41.79397825
0.00025507,42.13220624
0.000257534,42.47043422
0.000259998,42.80866221
0.000262463,43.1468902
0.000264927,43.48511819
0.000265755,43.70046058
0.000266582,43.91580297
0.00026741,44.13114535
0.000268237,44.34648774
0.000269065,44.56183013
0.000269892,44.77717252
0.00027072,44.99251491
0.000271547,45.20785729
0.000272375,45.42319968
0.000273202,45.63854207
0.00027403,45.85388446
0.000274857,46.06922684
0.000275685,46.28456923
0.000276512,46.49991162
0.000278156,46.74591689
0.0002798,46.99192216
0.000281444,47.23792743
0.000283088,47.4839327
0.000284732,47.72993797
0.000286376,47.97594324
0.000288021,48.22194852
0.000289665,48.46795379
0.000291309,48.71395906
0.000292953,48.95996433
0.000294597,49.2059696
0.000296241,49.45197487
0.000297885,49.69798014
0.000299529,49.94398541
0.000300355,50.12854788
0.00030118,50.31311035
0.000302006,50.49767282
0.000302832,50.68223529
0.000303657,50.86679776
0.000304483,51.05136023
0.000305308,51.2359227
0.000306134,51.42048517
0.00030696,51.60504764
0.000307785,51.78961011
0.000308611,51.97417258
0.000309437,52.15873505
0.000310262,52.34329752
0.000311088,52.52785999
0.000312734,52.80464518
0.00031438,53.08143037
0.000316026,53.35821556
0.000317672,53.63500074
0.000319318,53.91178593
0.000320964,54.18857112
0.00032261,54.46535631
0.000324255,54.7421415
0.000325901,55.01892669
0.000327547,55.29571188
0.000329193,55.57249706
0.000330839,55.84928225
0.000332485,56.12606744
0.000334131,56.40285263
0.000334959,56.61819502
0.000335786,56.8335374
0.000336614,57.04887979
0.000337441,57.26422218
0.000338269,57.47956457
0.000339096,57.69490695
0.000339923,57.91024934
0.000340751,58.12559173
0.000341579,58.34093411
0.000342406,58.5562765
0.000343234,58.77161889
0.000344061,58.98696128
0.000344888,59.20230366
0.000345716,59.41764605
0.00034736,59.66365132
0.000349004,59.90965659
0.000350648,60.15566186
0.000352292,60.40166713
0.000353936,60.6476724
0.00035558,60.89367767
0.000357225,61.13968295
0.000358869,61.38568822
0.000360513,61.63169349
0.000362157,61.87769876
0.000363801,62.12370403
0.000365445,62.3697093
0.000367089,62.61571457
0.000368733,62.86171984
0.000370373,63.04616528
0.000372014,63.23061071
0.000373655,63.41505615
0.000375295,63.59950159
0.000376935,63.78394702
0.000378576,63.96839246
0.000380217,64.1528379
0.000381857,64.33728333
0.000383497,64.52172877
0.000385138,64.7061742
0.000386779,64.89061964
0.000388419,65.07506508
0.000390059,65.25951051
0.0003917,65.44395595
0.000393344,65.68996122
0.000394988,65.93596649
0.000396632,66.18197176
0.000398276,66.42797703
0.00039992,66.6739823
0.000401564,66.91998757
0.000403209,67.16599285
0.000404853,67.41199812
0.000406497,67.65800339
0.000408141,67.90400866
0.000409785,68.15001393
0.000411429,68.3960192
0.000413073,68.64202447
0.000414717,68.88802974
0.000416361,69.13403501
0.000418005,69.38004028
0.000419649,69.62604555
0.000421293,69.87205082
0.000422937,70.11805609
0.000424581,70.36406136
0.000426226,70.61006664
0.00042787,70.85607191
0.000429514,71.10207718
0.000431158,71.34808245
0.000432802,71.59408772
0.000434446,71.84009299
0.00043609,72.08609826
0.000437734,72.33210353
0.00043856,72.516666
0.000439385,72.70122847
0.000440211,72.88579094
0.000441037,73.07035341
0.000441862,73.25491588
0.000442688,73.43947835
0.000443514,73.62404083
0.000444339,73.8086033
0.000445165,73.99316577
0.00044599,74.17772824
0.000446816,74.36229071
0.000447642,74.54685318
0.000448467,74.73141565
0.000449293,74.91597812
0.000450119,75.10054059
0.000450944,75.28510306
0.00045177,75.46966553
0.000452596,75.654228
0.000453422,75.83879047
0.000454247,76.02335294
0.000455073,76.20791541
0.000455899,76.39247788
0.000456724,76.57704035
0.00045755,76.76160282
0.000458376,76.94616529
0.000459202,77.13072776
0.000460027,77.31529023
0.000460853,77.4998527
0.000461679,77.68441517
0.000462504,77.86897764
0.00046333,78.05354011
0.000464156,78.23810258
0.000464981,78.42266505
0.000465807,78.60722752
0.000466633,78.79178999
0.000467458,78.97635246
0.000468284,79.16091493
0.000469109,79.3454774
0.000469935,79.53003987
0.000470761,79.71460234
0.000471586,79.89916481
0.000472412,80.08372728
0.000474871,80.32961552
0.00047733,80.57550375
0.000479789,80.82139199
0.000482247,81.06728023
0.000484706,81.31316847
0.000487165,81.5590567
0.000489624,81.80494494
0.000492083,82.05083318
0.000494542,82.29672141
0.000497001,82.54260965
0.000499459,82.78849789
0.000501918,83.03438613
0.000504377,83.28027436
0.000506836,83.5261626
0.000507671,83.86462466
0.000508506,84.20308671
0.00050934,84.54154877
0.000510175,84.88001083
0.00051101,85.21847288
0.000511845,85.55693494
0.00051268,85.895397
0.000513514,86.23385905
0.000514349,86.57232111
0.000515184,86.91078316
0.000516019,87.24924522
0.000516853,87.58770728
0.000517688,87.92616933
0.000518523,88.26463139
0.000520984,88.54129954
0.000523444,88.8179677
0.000525905,89.09463585
0.000528366,89.37130401
0.000530827,89.64797216
0.000533287,89.92464032
0.000535748,90.20130847
0.000538209,90.47797662
0.000540669,90.75464478
0.00054313,91.03131293
0.000545591,91.30798109
0.000548052,91.58464924
0.000550512,91.8613174
0.000552973,92.13798555
0.000554617,92.38399082
0.000556261,92.62999609
0.000557905,92.87600136
0.000559549,93.12200663
0.000561193,93.3680119
0.000562837,93.61401717
0.000564482,93.86002245
0.000566126,94.10602772
0.00056777,94.35203299
0.000569414,94.59803826
0.000571058,94.84404353
0.000572702,95.0900488
0.000574346,95.33605407
0.00057599,95.58205934
0.000576819,95.82818165
0.000577649,96.07430395
0.000578478,96.32042626
0.000579307,96.56654856
0.000580136,96.81267087
0.000580966,97.05879317
0.000581795,97.30491548
0.000582624,97.55103778
0.000583454,97.79716009
0.000584283,98.04328239
0.000585112,98.2894047
0.000585941,98.535527
0.000586771,98.78164931
0.0005876,99.02777161
0.000590063,99.33521968
0.000592525,99.64266775
0.000594988,99.95011582
0.00059745,100.2575639
0.000599913,100.565012
0.000602375,100.87246
0.000604838,101.1799081
0.0006073,101.4873562
0.000609763,101.7948042
0.000612225,102.1022523
0.000614688,102.4097004
0.00061715,102.7171485
0.000619613,103.0245965
0.000622075,103.3320446
0.000623723,103.6396097
0.00062537,103.9471748
0.000627018,104.2547399
0.000628666,104.562305
0.000630314,104.8698701
0.000631961,105.1774352
0.000633609,105.4850004
0.000635257,105.7925655
0.000636904,106.1001306
0.000638552,106.4076957
0.0006402,106.7152608
0.000641848,107.0228259
0.000643495,107.330391
0.000645143,107.6379561
0.000646791,107.9455212
0.000648438,108.2530863
0.000650086,108.5606514
0.000651734,108.8682165
0.000653382,109.1757816
0.000655029,109.4833467
0.000656677,109.7909119
0.000658325,110.098477
0.000659972,110.4060421
0.00066162,110.7136072
0.000663268,111.0211723
0.000664916,111.3287374
0.000666563,111.6363025
0.000668211,111.9438676
0.000671483,112.1588589
0.000674755,112.3738502
0.000678027,112.5888415
0.000681298,112.8038327
0.00068457,113.018824
0.000687842,113.2338153
0.000691114,113.4488066
0.000694386,113.6637979
0.000697658,113.8787892
0.00070093,114.0937805
0.000704201,114.3087717
0.000707473,114.523763
0.000710745,114.7387543
0.000714017,114.9537456
0.000718104,115.1686199
0.00072219,115.3834941
0.000726277,115.5983684
0.000730363,115.8132426
0.00073445,116.0281169
0.000738536,116.2429911
0.000742623,116.4578654
0.00074671,116.6727396
0.000750796,116.8876139
0.000754883,117.1024881
0.000758969,117.3173624
0.000763056,117.5322366
0.000767142,117.7471109
0.000771229,117.9619851
0.000773684,118.1463135
0.000776139,118.3306419
0.000778595,118.5149703
0.00078105,118.6992987
0.000783505,118.8836271
0.00078596,119.0679555
0.000788416,119.2522839
0.000790871,119.4366123
0.000793326,119.6209407
0.000795781,119.8052691
0.000798236,119.9895975
0.000800692,120.1739259
0.000803147,120.3582543
0.000805602,120.5425827
0.000810502,120.72656
0.000815401,120.9105373
0.000820301,121.0945146
0.0008252,121.2784919
0.0008301,121.4624692
0.000834999,121.6464465
0.000839899,121.8304238
0.000844798,122.0144011
0.000849698,122.1983784
0.000854597,122.3823557
0.000859497,122.566333
0.000864396,122.7503103
0.000869296,122.9342876
0.000874195,123.1182649
0.00087746,123.2101365
0.000880724,123.3020081
0.000883989,123.3938798
0.000887253,123.4857514
0.000890518,123.577623
0.000893782,123.6694946
0.000897047,123.7613663
0.000900311,123.8532379
0.000903576,123.9451095
0.00090684,124.0369811
0.000910105,124.1288527
0.000913369,124.2207244
0.000916634,124.312596
0.000919898,124.4044676
0.000923166,124.5578991
0.000926434,124.7113305
0.000929702,124.864762
0.000932971,125.0181934
0.000936239,125.1716249
0.000939507,125.3250563
0.000942775,125.4784878
0.000946043,125.6319192
0.000949311,125.7853507
0.000952579,125.9387821
0.000955848,126.0922136
0.000959116,126.245645
0.000962384,126.3990765
0.000965652,126.5525079
0.000970546,126.6441455
0.00097544,126.735783
0.000980334,126.8274206
0.000985228,126.9190581
0.000990122,127.0106957
0.000995016,127.1023332
0.00099991,127.1939708
0.001004805,127.2856083
0.001009699,127.3772459
0.001014593,127.4688834
0.001019487,127.560521
0.001024381,127.6521585
0.001029275,127.7437961
0.001034169,127.8354336
0.00103825,127.9579681
0.001042331,128.0805026
0.001046412,128.2030371
0.001050494,128.3255716
0.001054575,128.4481061
0.001058656,128.5706406
0.001062737,128.6931751
0.001066818,128.8157096
0.001070899,128.9382441
0.00107498,129.0607786
0.001079062,129.1833131
0.001083143,129.3058476
0.001087224,129.4283821
0.001091305,129.5509166
0.001096201,129.6733341
0.001101097,129.7957515
0.001105993,129.918169
0.001110888,130.0405865
0.001115784,130.1630039
0.00112068,130.2854214
0.001125576,130.4078389
0.001130472,130.5302563
0.001135368,130.6526738
0.001140264,130.7750912
0.001145159,130.8975087
0.001150055,131.0199262
0.001154951,131.1423436
0.001159847,131.2647611
0.001165558,131.3870615
0.001171268,131.509362
0.001176979,131.6316624
0.00118269,131.7539628
0.0011884,131.8762632
0.001194111,131.9985637
0.001199822,132.1208641
0.001205532,132.2431645
0.001211243,132.365465
0.001216953,132.4877654
0.001222664,132.6100658
0.001228375,132.7323662
0.001234085,132.8546667
0.001239796,132.9769671
0.001245509,133.1300475
0.001251221,133.2831278
0.001256934,133.4362082
0.001262646,133.5892885
0.001268359,133.7423689
0.001274071,133.8954492
0.001279784,134.0485296
0.001285496,134.2016099
0.001291209,134.3546903
0.001296921,134.5077706
0.001302634,134.660851
0.001308346,134.8139313
0.001314059,134.9670117
0.001319771,135.120092
0.001323852,135.2426265
0.001327933,135.365161
0.001332014,135.4876955
0.001336095,135.61023
0.001340176,135.7327645
0.001344257,135.855299
0.001348338,135.9778335
0.00135242,136.100368
0.001356501,136.2229025
0.001360582,136.345437
0.001364663,136.4679715
0.001368744,136.590506
0.001372825,136.7130405
0.001376906,136.835575
0.001381798,136.8964326
0.001386691,136.9572903
0.001391583,137.0181479
0.001396475,137.0790055
0.001401367,137.1398632
0.00140626,137.2007208
0.001411152,137.2615785
0.001416044,137.3224361
0.001420937,137.3832937
0.001425829,137.4441514
0.001430721,137.505009
0.001435613,137.5658666
0.001440506,137.6267243
0.001445398,137.6875819
0.001451923,137.8097653
0.001458449,137.9319487
0.001464974,138.0541321
0.0014715,138.1763155
0.001478025,138.2984989
0.001484551,138.4206823
0.001491076,138.5428657
0.001497601,138.665049
0.001504127,138.7872324
0.001510652,138.9094158
0.001517178,139.0315992
0.001523703,139.1537826
0.001530229,139.275966
0.001536754,139.3981494
0.001542463,139.4896699
0.001548172,139.5811904
0.00155388,139.6727109
0.001559589,139.7642315
0.001565298,139.855752
0.001571007,139.9472725
0.001576716,140.038793
0.001582424,140.1303135
0.001588133,140.221834
0.001593842,140.3133545
0.001599551,140.4048751
0.001605259,140.4963956
0.001610968,140.5879161
0.001616677,140.6794366
0.001624017,140.801503
0.001631357,140.9235693
0.001638698,141.0456357
0.001646038,141.1677021
0.001653378,141.2897684
0.001660718,141.4118348
0.001668059,141.5339012
0.001675399,141.6559675
0.001682739,141.7780339
0.001690079,141.9001002
0.001697419,142.0221666
0.00170476,142.144233
0.0017121,142.2662993
0.00171944,142.3883657
0.001725964,142.4797692
0.001732487,142.5711727
0.001739011,142.6625762
0.001745534,142.7539796
0.001752058,142.8453831
0.001758581,142.9367866
0.001765105,143.0281901
0.001771629,143.1195936
0.001778152,143.2109971
0.001784676,143.3024006
0.001791199,143.393804
0.001797723,143.4852075
0.001804246,143.576611
0.00181077,143.6680145
0.001820555,143.7897298
0.001830339,143.911445
0.001840123,144.0331603
0.001849908,144.1548755
0.001859693,144.2765908
0.001869477,144.398306
0.001879261,144.5200213
0.001889046,144.6417366
0.001898831,144.7634518
0.001908615,144.8851671
0.0019184,145.0068823
0.001928184,145.1285976
0.001937969,145.2503128
0.001947753,145.3720281
0.001955091,145.4633146
0.00196243,145.554601
0.001969768,145.6458875
0.001977106,145.7371739
0.001984445,145.8284604
0.001991783,145.9197468
0.001999122,146.0110333
0.00200646,146.1023197
0.002013798,146.1936062
0.002021137,146.2848926
0.002028475,146.3761791
0.002035813,146.4674655
0.002043152,146.558752
0.00205049,146.6500384
0.002059458,146.7410908
0.002068426,146.8321432
0.002077394,146.9231955
0.002086362,147.0142479
0.00209533,147.1053003
0.002104298,147.1963527
0.002113266,147.2874051
0.002122233,147.3784574
0.002131201,147.4695098
0.002140169,147.5605622
0.002149137,147.6516146
0.002158105,147.7426669
0.002167073,147.8337193
0.002176041,147.9247717
0.002185007,147.9850442
0.002193973,148.0453166
0.002202939,148.1055891
0.002211905,148.1658616
0.002220871,148.226134
0.002229837,148.2864065
0.002238804,148.346679
0.00224777,148.4069514
0.002256736,148.4672239
0.002265702,148.5274963
0.002274668,148.5877688
0.002283634,148.6480413
0.0022926,148.7083137
0.002301566,148.7685862
0.002308903,148.8290927
0.002316239,148.8895993
0.002323576,148.9501058
0.002330912,149.0106123
0.002338249,149.0711188
0.002345585,149.1316254
0.002352922,149.1921319
0.002360259,149.2526384
0.002367595,149.313145
0.002374932,149.3736515
0.002382268,149.434158
0.002389605,149.4946645
0.002396941,149.5551711
0.002404278,149.6156776
0.002412427,149.6452872
0.002420577,149.6748968
0.002428726,149.7045063
0.002436876,149.7341159
0.002445025,149.7637255
0.002453175,149.7933351
0.002461324,149.8229447
0.002469473,149.8525542
0.002477623,149.8821638
0.002485772,149.9117734
0.002493922,149.941383
0.002502071,149.9709925
0.002510221,150.0006021
0.00251837,150.0302117
0.002524894,150.1216152
0.002531417,150.2130187
0.002537941,150.3044221
0.002544465,150.3958256
0.002550988,150.4872291
0.002557512,150.5786326
0.002564036,150.6700361
0.002570559,150.7614395
0.002577083,150.852843
0.002583606,150.9442465
0.00259013,151.03565
0.002596654,151.1270534
0.002603177,151.2184569
0.002609701,151.3098604
0.002618667,151.3701329
0.002627633,151.4304053
0.002636599,151.4906778
0.002645565,151.5509503
0.002654531,151.6112227
0.002663497,151.6714952
0.002672463,151.7317677
0.00268143,151.7920401
0.002690396,151.8523126
0.002699362,151.912585
0.002708328,151.9728575
0.002717294,152.03313
0.00272626,152.0934024
0.002735226,152.1536749
0.002742561,152.1834015
0.002749895,152.2131281
0.00275723,152.2428547
0.002764565,152.2725813
0.0027719,152.3023079
0.002779234,152.3320345
0.002786569,152.3617612
0.002793904,152.3914878
0.002801238,152.4212144
0.002808573,152.450941
0.002815908,152.4806676
0.002823243,152.5103942
0.002830577,152.5401208
0.002837912,152.5698474
0.00284525,152.6611339
0.002852589,152.7524203
0.002859927,152.8437068
0.002867265,152.9349932
0.002874604,153.0262797
0.002881942,153.1175661
0.002889281,153.2088526
0.002896619,153.300139
0.002903957,153.3914254
0.002911296,153.4827119
0.002918634,153.5739983
0.002925972,153.6652848
0.002933311,153.7565712
0.002940649,153.8478577
0.00295043,153.9080131
0.002960211,153.9681686
0.002969992,154.028324
0.002979772,154.0884794
0.002989553,154.1486348
0.002999334,154.2087903
0.003009115,154.2689457
0.003018896,154.3291011
0.003028677,154.3892566
0.003038458,154.449412
0.003048238,154.5095674
0.003058019,154.5697228
0.0030678,154.6298783
0.003077581,154.6900337
0.00308736,154.7194092
0.003097139,154.7487847
0.003106918,154.7781602
0.003116697,154.8075357
0.003126476,154.8369112
0.003136255,154.8662867
0.003146035,154.8956623
0.003155814,154.9250378
0.003165593,154.9544133
0.003175372,154.9837888
0.003185151,155.0131643
0.00319493,155.0425398
0.003204709,155.0719153
0.003214488,155.1012908
0.003220193,155.1312515
0.003225898,155.1612122
0.003231603,155.1911728
0.003237309,155.2211335
0.003243014,155.2510942
0.003248719,155.2810549
0.003254424,155.3110155
0.003260129,155.3409762
0.003265834,155.3709369
0.003271539,155.4008976
0.003277245,155.4308583
0.00328295,155.4608189
0.003288655,155.4907796
0.00329436,155.5207403
0.003302511,155.5811298
0.003310663,155.6415193
0.003318814,155.7019088
0.003326965,155.7622983
0.003335117,155.8226878
0.003343268,155.8830773
0.00335142,155.9434668
0.003359571,156.0038563
0.003367722,156.0642458
0.003375874,156.1246353
0.003384025,156.1850248
0.003392176,156.2454143
0.003400328,156.3058038
0.003408479,156.3661933
0.003419076,156.4570116
0.003429674,156.5478299
0.003440271,156.6386482
0.003450869,156.7294665
0.003461466,156.8202848
0.003472064,156.9111031
0.003482661,157.0019215
0.003493258,157.0927398
0.003503856,157.1835581
0.003514453,157.2743764
0.003525051,157.3651947
0.003535648,157.456013
0.003546246,157.5468313
0.003556843,157.6376496
0.003567435,157.6361282
0.003578027,157.6346067
0.003588619,157.6330853
0.003599211,157.6315639
0.003609803,157.6300424
0.003620395,157.628521
0.003630987,157.6269996
0.003641578,157.6254781
0.00365217,157.6239567
0.003662762,157.6224352
0.003673354,157.6209138
0.003683946,157.6193924
0.003694538,157.6178709
0.00370513,157.6163495
0.003714909,157.645725
0.003724688,157.6751005
0.003734467,157.704476
0.003744246,157.7338515
0.003754025,157.763227
0.003763804,157.7926025
0.003773584,157.8219781
0.003783363,157.8513536
0.003793142,157.8807291
0.003802921,157.9101046
0.0038127,157.9394801
0.003822479,157.9688556
0.003832258,157.9982311
0.003842037,158.0276066
0.003849374,158.0881131
0.00385671,158.1486197
0.003864047,158.2091262
0.003871383,158.2696327
0.00387872,158.3301392
0.003886056,158.3906458
0.003893393,158.4511523
0.00390073,158.5116588
0.003908066,158.5721654
0.003915403,158.6326719
0.003922739,158.6931784
0.003930076,158.7536849
0.003937412,158.8141915
0.003944749,158.874698
0.003953715,158.9349705
0.003962681,158.9952429
0.003971647,159.0555154
0.003980613,159.1157879
0.003989579,159.1760603
0.003998545,159.2363328
0.004007512,159.2966053
0.004016478,159.3568777
0.004025444,159.4171502
0.00403441,159.4774226
0.004043376,159.5376951
0.004052342,159.5979676
0.004061308,159.65824
0.004070274,159.7185125
0.004076792,159.7175762
0.00408331,159.71664
0.004089828,159.7157037
0.004096347,159.7147674
0.004102865,159.7138311
0.004109383,159.7128949
0.004115901,159.7119586
0.004122419,159.7110223
0.004128937,159.7100861
0.004135455,159.7091498
0.004141974,159.7082135
0.004148492,159.7072772
0.00415501,159.706341
0.004161528,159.7054047
0.004168046,159.7044684
0.004174564,159.7035322
0.004181082,159.7025959
0.004187601,159.7016596
0.004194119,159.7007233
0.004200637,159.6997871
0.004207155,159.6988508
0.004213673,159.6979145
0.004220191,159.6969783
0.004226709,159.696042
0.004233228,159.6951057
0.004239746,159.6941694
0.004246264,159.6932332
0.004252782,159.6922969
0.004260117,159.7220235
0.004267451,159.7517501
0.004274786,159.7814767
0.004282121,159.8112034
0.004289456,159.84093
0.00429679,159.8706566
0.004304125,159.9003832
0.00431146,159.9301098
0.004318794,159.9598364
0.004326129,159.989563
0.004333464,160.0192897
0.004340799,160.0490163
0.004348133,160.0787429
0.004355468,160.1084695
0.004362803,160.1381961
0.004370137,160.1679227
0.004377472,160.1976493
0.004384807,160.2273759
0.004392142,160.2571025
0.004399476,160.2868291
0.004406811,160.3165558
0.004414146,160.3462824
0.00442148,160.376009
0.004428815,160.4057356
0.00443615,160.4354622
0.004443485,160.4651888
0.004450819,160.4949154
0.004458154,160.524642
0.004467116,160.5233546
0.004476079,160.5220673
0.004485041,160.5207799
0.004494004,160.5194925
0.004502966,160.5182051
0.004511929,160.5169178
0.004520891,160.5156304
0.004529853,160.514343
0.004538816,160.5130557
0.004547778,160.5117683
0.004556741,160.5104809
0.004565703,160.5091935
0.004574666,160.5079062
0.004583628,160.5066188
0.004590963,160.5363454
0.004598297,160.566072
0.004605632,160.5957986
0.004612967,160.6255253
0.004620302,160.6552519
0.004627636,160.6849785
0.004634971,160.7147051
0.004642306,160.7444317
0.00464964,160.7741583
0.004656975,160.8038849
0.00466431,160.8336116
0.004671645,160.8633382
0.004678979,160.8930648
0.004686314,160.9227914
0.00469528,160.9830639
0.004704246,161.0433363
0.004713212,161.1036088
0.004722179,161.1638813
0.004731145,161.2241537
0.004740111,161.2844262
0.004749077,161.3446987
0.004758043,161.4049711
0.004767009,161.4652436
0.004775975,161.525516
0.004784942,161.5857885
0.004793908,161.646061
0.004802874,161.7063334
0.00481184,161.7666059
0.004821619,161.7959814
0.004831398,161.8253569
0.004841177,161.8547324
0.004850956,161.8841079
0.004860735,161.9134834
0.004870514,161.9428589
0.004880293,161.9722345
0.004890072,162.00161
0.004899851,162.0309855
0.00490963,162.060361
0.004919409,162.0897365
0.004929188,162.119112
0.004938967,162.1484875
0.004948746,162.177863
0.004954451,162.2078237
0.004960156,162.2377844
0.004965862,162.267745
0.004971567,162.2977057
0.004977272,162.3276664
0.004982977,162.3576271
0.004988683,162.3875878
0.004994388,162.4175484
0.005000093,162.4475091
0.005005798,162.4774698
0.005011503,162.5074305
0.005017209,162.5373911
0.005022914,162.5673518
0.005028619,162.5973125
0.005036769,162.6269221
0.005044918,162.6565317
0.005053067,162.6861412
0.005061217,162.7157508
0.005069367,162.7453604
0.005077516,162.77497
0.005085665,162.8045796
0.005093815,162.8341891
0.005101965,162.8637987
0.005110114,162.8934083
0.005118263,162.9230179
0.005126413,162.9526274
0.005134563,162.982237
0.005142712,163.0118466
0.005154119,163.0102081
0.005165525,163.0085697
0.005176932,163.0069312
0.005188339,163.0052927
0.005199746,163.0036542
0.005211152,163.0020158
0.005222559,163.0003773
0.005233966,162.9987388
0.005245372,162.9971004
0.005256779,162.9954619
0.005268186,162.9938234
0.005279593,162.9921849
0.005290999,162.9905465
0.005302406,162.988908
0.005313816,163.0488294
0.005325227,163.1087507
0.005336637,163.1686721
0.005348047,163.2285934
0.005359458,163.2885148
0.005370868,163.3484361
0.005382279,163.4083575
0.005393689,163.4682789
0.005405099,163.5282002
0.00541651,163.5881216
0.00542792,163.6480429
0.00543933,163.7079643
0.005450741,163.7678856
0.005462151,163.827807
0.005471115,163.8572995
0.00548008,163.8867921
0.005489044,163.9162846
0.005498008,163.9457772
0.005506972,163.9752697
0.005515937,164.0047623
0.005524901,164.0342548
0.005533865,164.0637473
0.00554283,164.0932399
0.005551794,164.1227324
0.005560758,164.152225
0.005569722,164.1817175
0.005578687,164.2112101
0.005587651,164.2407026
0.005596615,164.2701951
0.00560558,164.2996877
0.005614544,164.3291802
0.005623508,164.3586728
0.005632472,164.3881653
0.005641437,164.4176579
0.005650401,164.4471504
0.005659365,164.4766429
0.00566833,164.5061355
0.005677294,164.535628
0.005686258,164.5651206
0.005695222,164.5946131
0.005704187,164.6241057
0.005713151,164.6535982
0.005721302,164.7139877
0.005729454,164.7743772
0.005737605,164.8347667
0.005745756,164.8951562
0.005753907,164.9555457
0.005762059,165.0159352
0.00577021,165.0763247
0.005778361,165.1367142
0.005786513,165.1971037
0.005794664,165.2574932
0.005802815,165.3178827
0.005810966,165.3782722
0.005819118,165.4386617
0.005827269,165.4990512
0.005832158,165.498349
0.005837046,165.4976468
0.005841935,165.4969446
0.005846824,165.4962424
0.005851712,165.4955402
0.005856601,165.494838
0.00586149,165.4941358
0.005866378,165.4934335
0.005871267,165.4927313
0.005876155,165.4920291
0.005881044,165.4913269
0.005885933,165.4906247
0.005890821,165.4899225
0.00589571,165.4892203
0.005901415,165.519181
0.00590712,165.5491417
0.005912825,165.5791024
0.005918531,165.609063
0.005924236,165.6390237
0.005929941,165.6689844
0.005935646,165.6989451
0.005939449,165.7189189